Workbook

Sheet Sheet1
A1: UsuariId | B1: ProdId | C1: Fons | D1: IdMov | E1: Data | F1: TipusMov | G1: Parts | H1: PreuPart | I1: Import | K1: PreuPartReal | L1: Dif
A2: 1 | B2: 10 | C2: Bolsa Tecnología y Telecomunicaciones FI | D2: 15 | E2: 36841 | F2: 0 | G2: 679.64 | H2: 22.99204 | I2: =G2*H2 -> 15626.31
A3: 1 | B3: 11 | C3: Total Return N Acc €-H1 | D3: 16 | E3: 41166 | F3: 0 | G3: 547.64513 | H3: 18.26 | I3: =G3*H3 -> 10000 | K3: =Sheet2!E2 -> 18.26 | L3: =IF(ROUND(H3-K3,2)=0,"",H3-K3) | N3: =Sheet2!C2 -> Templeton Global Ttl Ret N(acc)EUR-H1
A4: 1 | B4: 12 | C4: American Extended Alpha R USD Acc | D4: 32 | E4: 41166 | F4: 0 | G4: 5006.5079 | H4: 1.9974 | I4: =G4*H4 -> 9999.9989 | K4: =Sheet2!E3 -> 2 | L4: =IF(ROUND(H4-K4,2)=0,"",H4-K4) | N4: =Sheet2!C3 -> Threadneedle Amer Extnd Alpha Rtl AccUSD
A5: 1 | B5: 3 | C5: Asian Smaller Companies Fund | D5: 1 | E5: 41172 | F5: 0 | G5: 325.522 | H5: 30.719859 | I5: =G5*H5 -> 9999.99 | K5: =Sheet2!E4 -> 30.72 | L5: =IF(ROUND(H5-K5,2)=0,"",H5-K5) | N5: =Sheet2!C4 -> abrdnI-Asian Smaller Companies A Acc USD
A6: 1 | B6: 3 | C6: Asian Smaller Companies Fund | D6: 2 | E6: 41187 | F6: 0 | G6: 1267.688 | H6: 31.55349 | I6: =G6*H6 -> 39999.98 | K6: =Sheet2!E5 -> 31.55 | L6: =IF(ROUND(H6-K6,2)=0,"",H6-K6) | N6: =Sheet2!C5 -> abrdnI-Asian Smaller Companies A Acc USD
A7: 1 | B7: 14 | C7: Patrimoine A EUR Acc | D7: 35 | E7: 41201 | F7: 0 | G7: 21.84 | H7: 549.56456 | I7: =G7*H7 -> 12002.49 | L7: =IF(ROUND(H7-K7,2)=0,"",H7-K7) -> 549.56456
A8: 1 | B8: 11 | C8: Total Return N Acc €-H1 | D8: 17 | E8: 41377 | F8: 0 | G8: 1010.611 | H8: 19.789998 | I8: =G8*H8 -> 19999.99 | K8: =Sheet2!E6 -> 19.79 | L8: =IF(ROUND(H8-K8,2)=0,"",H8-K8) | N8: =Sheet2!C6 -> Templeton Global Ttl Ret N(acc)EUR-H1
A9: 1 | B9: 11 | C9: Total Return N Acc €-H1 | D9: 24 | E9: 41383 | F9: 0 | G9: 280.07 | H9: 19.679973 | I9: =G9*H9 -> 5511.77 | K9: =Sheet2!E7 -> 19.68 | L9: =IF(ROUND(H9-K9,2)=0,"",H9-K9) | N9: =Sheet2!C7 -> Templeton Global Ttl Ret N(acc)EUR-H1
A10: 1 | B10: 13 | C10: Indonesia Fund A-USD | D10: 34 | E10: 41385 | F10: 0 | G10: 394.85 | H10: 26.279093 | I10: =G10*H10 -> 10376.3 | K10: =Sheet2!E10 -> 26.28 | L10: =IF(ROUND(H10-K10,2)=0,"",H10-K10) | N10: =Sheet2!C10 -> Fidelity Indonesia A-Dis-USD
A11: 1 | B11: 3 | C11: Asian Smaller Companies Fund | D11: 3 | E11: 41410 | F11: 0 | G11: 522.374 | H11: 38.286783 | I11: =G11*H11 -> 20000.02 | K11: =Sheet2!E11 -> 38.29 | L11: =IF(ROUND(H11-K11,2)=0,"",H11-K11) | N11: =Sheet2!C11 -> abrdnI-Asian Smaller Companies A Acc USD
A12: 1 | B12: 5 | C12: DWS Deutschland LC | D12: 26 | E12: 41439 | F12: 0 | G12: 249.3471 | H12: 139.70999 | I12: =G12*H12 -> 34836.28 | K12: =Sheet2!E12 -> 139.71 | L12: =IF(ROUND(H12-K12,2)=0,"",H12-K12)
A13: 1 | B13: 6 | C13: Biotechnology C USD Acc | D13: 7 | E13: 41492 | F13: 0 | G13: 24.092 | H13: 250.44123 | I13: =G13*H13 -> 6033.63 | K13: =Sheet2!E17 -> 250.44 | L13: =IF(ROUND(H13-K13,2)=0,"",H13-K13) | N13: =Sheet2!C17 -> Candriam Eqs L Biotech C USD Cap
A14: 1 | B14: 1 | C14: Optimal Income A-H Grs Acc Hdg EUR | D14: 27 | E14: 41521 | F14: 0 | G14: 58.502 | H14: 17.093262 | I14: =G14*H14 -> 999.99 | K14: =Sheet2!E19 -> 17.09 | L14: =IF(ROUND(H14-K14,2)=0,"",H14-K14) | N14: =Sheet2!C19 -> M G Optimal Income Euro A-H Acc
A15: 1 | B15: 2 | C15: European Growth N Acc ? | D15: 37 | E15: 41534 | F15: 0 | G15: 76.746 | H15: 13.029995 | I15: =G15*H15 -> 1000 | K15: =Sheet2!E20 -> 13.03 | L15: =IF(ROUND(H15-K15,2)=0,"",H15-K15) | N15: =Sheet2!C20 -> Templeton European Opps N(acc)EUR
A16: 1 | B16: 4 | C16: Thailand A-USD | D16: 11 | E16: 41554 | F16: 0 | G16: 28.28 | H16: 35.357143 | I16: =G16*H16 -> 999.9 | K16: =Sheet2!E21 -> 35.36 | L16: =IF(ROUND(H16-K16,2)=0,"",H16-K16) | N16: =Sheet2!C21 -> Fidelity Thailand A-Dis-USD
A17: 1 | B17: 4 | C17: Thailand A-USD | D17: 12 | E17: 41565 | F17: 0 | G17: 134.86 | H17: 37.076301 | I17: =G17*H17 -> 5000.11 | K17: =Sheet2!E22 -> 37.08 | L17: =IF(ROUND(H17-K17,2)=0,"",H17-K17) | N17: =Sheet2!C22 -> Fidelity Thailand A-Dis-USD
A18: 1 | B18: 6 | C18: Biotechnology C USD Acc | D18: 39 | E18: 41673 | F18: 0 | G18: 3.144 | H18: 304.86641 | I18: =G18*H18 -> 958.5 | K18: =Sheet2!E23 -> 304.86 | L18: =IF(ROUND(H18-K18,2)=0,"",H18-K18) -> 0.0064122137 | M18: =L18*G18 -> 0.02016 | N18: =Sheet2!C23 -> Candriam Eqs L Biotech C USD Cap
A19: 1 | B19: 1 | C19: Optimal Income A-H Grs Acc Hdg EUR | D19: 29 | E19: 41794 | F19: 0 | G19: 2347.326 | H19: 18.249685 | I19: =G19*H19 -> 42837.96 | K19: =Sheet2!E24 -> 18.25 | L19: =IF(ROUND(H19-K19,2)=0,"",H19-K19) | N19: =Sheet2!C24 -> M G Optimal Income Euro A-H Acc
A20: 1 | B20: 5 | C20: DWS Deutschland LC | D20: 31 | E20: 41976 | F20: 0 | G20: 264.1805 | H20: 168.57001 | I20: =G20*H20 -> 44532.91 | K20: =Sheet2!E29 -> 168.57 | L20: =IF(ROUND(H20-K20,2)=0,"",H20-K20) | N20: =Sheet2!C29 -> 0
A21: 1 | B21: 3 | C21: Asian Smaller Companies Fund | D21: 41 | E21: 42047 | F21: 0 | G21: 174.229 | H21: 39.429136 | I21: =G21*H21 -> 6869.699 | K21: =Sheet2!E35 -> 39.43 | L21: =IF(ROUND(H21-K21,2)=0,"",H21-K21) | N21: =Sheet2!C35 -> abrdnI-Asian Smaller Companies A Acc USD
A22: 1 | B22: 1 | C22: Optimal Income A-H Grs Acc Hdg EUR | D22: 92 | E22: 42202.719 | F22: 0 | G22: 2922.36 | H22: 18.3931 | I22: =G22*H22 -> 53751.26 | K22: =Sheet2!E36 -> 18.39 | L22: =IF(ROUND(H22-K22,2)=0,"",H22-K22) | N22: =Sheet2!C36 -> M G Optimal Income Euro A-H Acc
A23: 1 | B23: 6 | C23: Biotechnology C USD Acc | D23: 96 | E23: 42208.759 | F23: 0 | G23: 10.043 | H23: 591.12317 | I23: =G23*H23 -> 5936.65 | K23: =Sheet2!E43 -> 591.15 | L23: =IF(ROUND(H23-K23,2)=0,"",H23-K23) -> -0.026829633 | M23: =L23*G23 -> -0.26945 | N23: =Sheet2!C43 -> Candriam Eqs L Biotech C USD Cap
A24: 1 | B24: 15 | C24: Templeton Emerging Mkts Sm Cos N Acc $ | D24: 98 | E24: 42219.795 | F24: 0 | G24: 112.246 | H24: 8.9090034 | I24: =G24*H24 -> 1000 | K24: =Sheet2!E44 -> 8.91 | L24: =IF(ROUND(H24-K24,2)=0,"",H24-K24) | N24: =Sheet2!C44 -> Templeton Em Mkts Smlr Coms N(acc)USD
A25: 1 | B25: 16 | C25: DWS Aktien Strategie Deutschland | D25: 101 | E25: 42279.464 | F25: 0 | G25: 160.7528 | H25: 323.52998 | I25: =G25*H25 -> 52008.35 | K25: =Sheet2!E45 -> 323.53 | L25: =IF(ROUND(H25-K25,2)=0,"",H25-K25) | N25: =Sheet2!C45 -> 0
A26: 1 | B26: 6 | C26: Biotechnology C USD Acc | D26: 104 | E26: 42311.831 | F26: 0 | G26: 0.047 | H26: 507.02128 | I26: =G26*H26 -> 23.83 | K26: =Sheet2!E51 -> 507.43 | L26: =IF(ROUND(H26-K26,2)=0,"",H26-K26) -> -0.4087234 | M26: =L26*G26 -> -0.01921 | N26: =Sheet2!C51 -> Candriam Eqs L Biotech C USD Cap
A27: 1 | B27: 19 | C27: Trea Renta Fija Ahorro S FI | D27: 108 | E27: 42387.493 | F27: 0 | G27: 0.5375 | H27: 1860.4651 | I27: =G27*H27 -> 1000 | K27: =Sheet2!E52 -> 1860.41 | L27: =IF(ROUND(H27-K27,2)=0,"",H27-K27) -> 0.055116279 | M27: =L27*G27 -> 0.029625 | N27: =Sheet2!C52 -> Trea Renta Fija Ahorro S FI
A28: 1 | B28: 15 | C28: Templeton Emerging Mkts Sm Cos N Acc $ | D28: 122 | E28: 42635.715 | F28: 0 | G28: 5585.159 | H28: 8.952 | I28: =G28*H28 -> 49998.343 | K28: =Sheet2!E55 -> 8.95 | L28: =IF(ROUND(H28-K28,2)=0,"",H28-K28) | N28: =Sheet2!C55 -> Templeton Em Mkts Smlr Coms N(acc)USD
A29: 1 | B29: 19 | C29: Trea Renta Fija Ahorro S FI | D29: 171 | E29: 43516.388 | F29: 0 | G29: 0.4678 | H29: 1895.2417 | I29: =G29*H29 -> 886.59407 | K29: =Sheet2!E56 -> 1895.25 | L29: =IF(ROUND(H29-K29,2)=0,"",H29-K29) -> -0.0083 | M29: =L29*G29 -> -0.00388274 | N29: =Sheet2!C56 -> Trea Renta Fija Ahorro S FI
A30: 1 | B30: 27 | C30: Global Technology Fund A-acc-eur | D30: 173 | E30: 43525.444 | F30: 0 | G30: 1778.69 | H30: 17.05 | I30: =G30*H30 -> 30326.665 | K30: =Sheet2!E57 -> 17.05 | L30: =IF(ROUND(H30-K30,2)=0,"",H30-K30) | N30: =Sheet2!C57 -> Fidelity Global Technology A-ACC-EUR
A31: 1 | B31: 28 | C31: Euro Fund A-2 Acc | D31: 197 | E31: 44473.585 | F31: 0 | G31: 24.54 | H31: 435.10187 | I31: =G31*H31 -> 10677.4 | K31: =Sheet2!E58 -> 435.1 | L31: =IF(ROUND(H31-K31,2)=0,"",H31-K31) | N31: =Sheet2!C58 -> abrdn Euro Fund A-2
A32: 1 | B32: 29 | C32: CS Corto Plazo B FI | D32: 199 | E32: 44476.939 | F32: 0 | G32: 765.3691 | H32: 13.039504 | I32: =G32*H32 -> 9980.0331 | K32: =Sheet2!E59 -> 13.04 | L32: =IF(ROUND(H32-K32,2)=0,"",H32-K32) | N32: =Sheet2!C59 -> CS Corto Plazo B FI
A33: 1 | B33: 19 | C33: Trea Renta Fija Ahorro S FI | D33: 201 | E33: 44477.939 | F33: 0 | G33: 5.1658 | H33: 1904.1616 | I33: =G33*H33 -> 9836.5181 | K33: =Sheet2!E60 -> 1904.16 | L33: =IF(ROUND(H33-K33,2)=0,"",H33-K33) | N33: =Sheet2!C60 -> Trea Renta Fija Ahorro S FI
A34: 1 | B34: 28 | C34: Euro Fund A-2 Acc | D34: 203 | E34: 44496.481 | F34: 0 | G34: 34.724 | H34: 434.94679 | I34: =G34*H34 -> 15103.092 | K34: =Sheet2!E61 -> 434.94 | L34: =IF(ROUND(H34-K34,2)=0,"",H34-K34) -> 0.0067941481 | M34: =L34*G34 -> 0.23592 | N34: =Sheet2!C61 -> abrdn Euro Fund A-2
A35: 1 | B35: 28 | C35: Euro Fund A-2 Acc | D35: 205 | E35: 44524.517 | F35: 0 | G35: 46.266 | H35: 434.75771 | I35: =G35*H35 -> 20114.5 | K35: =Sheet2!E62 -> 434.76 | L35: =IF(ROUND(H35-K35,2)=0,"",H35-K35) | N35: =Sheet2!C62 -> abrdn Euro Fund A-2
A36: 1 | B36: 28 | C36: Euro Fund A-2 Acc | D36: 217 | E36: 44725.295 | F36: 0 | G36: 23.23 | H36: 433.28309 | I36: =G36*H36 -> 10065.166 | K36: =Sheet2!E63 -> 433.29 | L36: =IF(ROUND(H36-K36,2)=0,"",H36-K36) -> -0.0069091692 | M36: =L36*G36 -> -0.1605 | N36: =Sheet2!C63 -> abrdn Euro Fund A-2
A37: 1 | B37: 30 | C37: BGF World Energy E2 | D37: 219 | E37: 44736.475 | F37: 0 | G37: 565.1 | H37: 17.241866 | I37: =G37*H37 -> 9743.3787 | K37: =Sheet2!E64 -> 17.24 | L37: =IF(ROUND(H37-K37,2)=0,"",H37-K37) | N37: =Sheet2!C64 -> BGF World Energy E2
A38: 1 | B38: 1036 | C38: CS (Lux) Commodity Idx Plus USD B | D38: 1228 | E38: 44832.415 | F38: 0 | G38: 130.14 | H38: 76.532599 | I38: =G38*H38 -> 9959.9524 | K38: =Sheet2!E65 -> 76.53 | L38: =IF(ROUND(H38-K38,2)=0,"",H38-K38) | N38: =Sheet2!C65 -> CS (Lux) Commodity Idx Plus USD B
A39: 1 | B39: 1037 | C39: Threadneedle (Lux) Enhanced | D39: 1231 | E39: 44861.454 | F39: 0 | G39: 810.714 | H39: 10.282473 | I39: =G39*H39 -> 8336.1445 | K39: =Sheet2!E66 -> 10.28 | L39: =IF(ROUND(H39-K39,2)=0,"",H39-K39) | N39: =Sheet2!C66 -> Threadneedle (Lux) Enhanced Cmdts DU
A40: 1 | B40: 1038 | C40: Abrdn US Dollar Fund A-2 | D40: 1233 | E40: 44879.428 | F40: 0 | G40: 0.83 | H40: 3310.2667 | I40: =G40*H40 -> 2747.5214 | K40: =Sheet2!E67 -> 3308.42 | L40: =IF(ROUND(H40-K40,2)=0,"",H40-K40) -> 1.8466874 | M40: =L40*G40 -> 1.5327505 | N40: =Sheet2!C67 -> abrdn US Dollar Fund A-2
...

Sheet Sheet2
A1: Fecha | B1: Movimiento | C1: Valor | D1: Cantidad | E1: Precio Ejecución | F1: Importe Bruto | G1: Importe total | H1: Plusvalía/Minusvalía
A2: 41169 | B2: Suscripción fondo | C2: Templeton Global Ttl Ret N(acc)EUR-H1 | D2: 547.65 | E2: 18.26 | F2: -10000 | G2: -10000
A3: 41169 | B3: Suscripción fondo | C3: Threadneedle Amer Extnd Alpha Rtl AccUSD | D3: 5006.51 | E3: 2 | F3: -10000 | G3: -10000
A4: 41172 | B4: Suscripción fondo | C4: abrdnI-Asian Smaller Companies A Acc USD | D4: 325.52 | E4: 30.72 | F4: -10000.01 | G4: -10000.01
A5: 41187 | B5: Suscripción fondo | C5: abrdnI-Asian Smaller Companies A Acc USD | D5: 1267.69 | E5: 31.55 | F5: -39999.98 | G5: -39999.98
A6: 41375 | B6: Suscripción fondo | C6: Templeton Global Ttl Ret N(acc)EUR-H1 | D6: 1010.61 | E6: 19.79 | F6: -19999.99 | G6: -19999.99
A7: 41381 | B7: Suscripción traspaso de fondo | C7: Templeton Global Ttl Ret N(acc)EUR-H1 | D7: 12.65 | E7: 19.68 | F7: -248.93 | G7: 0
A8: 41381 | B8: Suscripción traspaso de fondo | C8: Templeton Global Ttl Ret N(acc)EUR-H1 | D8: 68.92 | E8: 19.68 | F8: -1356.24 | G8: 0
A9: 41381 | B9: Suscripción traspaso de fondo | C9: Templeton Global Ttl Ret N(acc)EUR-H1 | D9: 198.51 | E9: 19.68 | F9: -3906.6 | G9: 0
A10: 41387 | B10: Suscripción traspaso de fondo | C10: Fidelity Indonesia A-Dis-USD | D10: 394.85 | E10: 26.28 | F10: -10376.3 | G10: 0
A11: 41409 | B11: Suscripción fondo | C11: abrdnI-Asian Smaller Companies A Acc USD | D11: 522.37 | E11: 38.29 | F11: -20000.02 | G11: -20000.02
A12: 41437 | B12: Suscripción traspaso de fondo | D12: 1.72 | E12: 139.71 | F12: -239.7 | G12: 0
A13: 41437 | B13: Suscripción traspaso de fondo | D13: 9.35 | E13: 139.71 | F13: -1305.94 | G13: 0
A14: 41437 | B14: Suscripción traspaso de fondo | D14: 26.93 | E14: 139.71 | F14: -3761.69 | G14: 0
A15: 41437 | B15: Suscripción traspaso de fondo | D15: 74.28 | E15: 139.71 | F15: -10377.87 | G15: 0
A16: 41437 | B16: Suscripción traspaso de fondo | D16: 137.08 | E16: 139.71 | F16: -19151.08 | G16: 0
A17: 41492 | B17: Suscripción traspaso de fondo | C17: Candriam Eqs L Biotech C USD Cap | D17: 24.04 | E17: 250.44 | F17: -6020.89 | G17: 0
A18: 41492 | B18: Suscripción traspaso de fondo | C18: Candriam Eqs L Biotech C USD Cap | D18: 0.05 | E18: 250.44 | F18: -12.67 | G18: 0
A19: 41519 | B19: Suscripción fondo | C19: M G Optimal Income Euro A-H Acc | D19: 58.5 | E19: 17.09 | F19: -999.99 | G19: -999.99
A20: 41530 | B20: Suscripción fondo | C20: Templeton European Opps N(acc)EUR | D20: 76.75 | E20: 13.03 | F20: -1000 | G20: -1000
A21: 41554 | B21: Suscripción fondo | C21: Fidelity Thailand A-Dis-USD | D21: 28.28 | E21: 35.36 | F21: -999.9 | G21: -999.9
A22: 41563 | B22: Suscripción fondo | C22: Fidelity Thailand A-Dis-USD | D22: 134.86 | E22: 37.08 | F22: -5000.11 | G22: -5000.11
A23: 41669 | B23: Suscripción traspaso de fondo | C23: Candriam Eqs L Biotech C USD Cap | D23: 3.14 | E23: 304.86 | F23: -958.5 | G23: 0
A24: 41793 | B24: Suscripción traspaso de fondo | C24: M G Optimal Income Euro A-H Acc | D24: 16.17 | E24: 18.25 | F24: -295.17 | G24: 0
A25: 41793 | B25: Suscripción traspaso de fondo | C25: M G Optimal Income Euro A-H Acc | D25: 88.12 | E25: 18.25 | F25: -1608.14 | G25: 0
A26: 41793 | B26: Suscripción traspaso de fondo | C26: M G Optimal Income Euro A-H Acc | D26: 253.82 | E26: 18.25 | F26: -4632.18 | G26: 0
A27: 41793 | B27: Suscripción traspaso de fondo | C27: M G Optimal Income Euro A-H Acc | D27: 700.25 | E27: 18.25 | F27: -12779.39 | G27: 0
A28: 41793 | B28: Suscripción traspaso de fondo | C28: M G Optimal Income Euro A-H Acc | D28: 1288.96 | E28: 18.25 | F28: -23523.08 | G28: 0
A29: 41976 | B29: Suscripción traspaso de fondo | D29: 1.78 | E29: 168.57 | F29: -299.62 | G29: 0
A30: 41976 | B30: Suscripción traspaso de fondo | D30: 9.68 | E30: 168.57 | F30: -1632.36 | G30: 0
A31: 41976 | B31: Suscripción traspaso de fondo | D31: 27.89 | E31: 168.57 | F31: -4701.93 | G31: 0
A32: 41976 | B32: Suscripción traspaso de fondo | D32: 76.95 | E32: 168.57 | F32: -12971.84 | G32: 0
A33: 41976 | B33: Suscripción traspaso de fondo | D33: 141.65 | E33: 168.57 | F33: -23877.3 | G33: 0
A34: 41976 | B34: Suscripción traspaso de fondo | D34: 6.23 | E34: 168.57 | F34: -1049.86 | G34: 0
A35: 42046 | B35: Suscripción traspaso de fondo | C35: abrdnI-Asian Smaller Companies A Acc USD | D35: 174.23 | E35: 39.43 | F35: -6869.7 | G35: 0
A36: 42202 | B36: Suscripción traspaso de fondo | C36: M G Optimal Income Euro A-H Acc | D36: 20.01 | E36: 18.39 | F36: -368.12 | G36: 0
A37: 42202 | B37: Suscripción traspaso de fondo | C37: M G Optimal Income Euro A-H Acc | D37: 109.04 | E37: 18.39 | F37: -2005.57 | G37: 0
A38: 42202 | B38: Suscripción traspaso de fondo | C38: M G Optimal Income Euro A-H Acc | D38: 314.08 | E38: 18.39 | F38: -5776.92 | G38: 0
A39: 42202 | B39: Suscripción traspaso de fondo | C39: M G Optimal Income Euro A-H Acc | D39: 866.5 | E39: 18.39 | F39: -15937.59 | G39: 0
A40: 42202 | B40: Suscripción traspaso de fondo | C40: M G Optimal Income Euro A-H Acc | D40: 1594.96 | E40: 18.39 | F40: -29336.35 | G40: 0
...
