Workbook

Sheet Taula Moviments Sencera
A1: UsuariId | B1: ProdId | C1: Id | D1: Mov | E1: Trasp | F1: Mov | G1: Participacions | H1: Part acum | I1: Mov Id Venda | J1: Prod Id Traspas | K1: Data | L1: Preu Parti Origen | M1: Preu Participacio | N1: Despeses | O1: Descripcio
A2: 1 | B2: 1 | C2: 27 | D2: 0 | E2: =IF(J2>0,"Si","") | F2: =IF(D2=0,"Compra","Venda") -> Compra | G2: 58.502 | H2: =G2 -> 58.502 | K2: 41521 | L2: 17.0933 | M2: 17.093262 | O2: Compra inicial.
A3: 1 | B3: 1 | C3: 29 | D3: 0 | E3: =IF(J3>0,"Si","") -> Si | F3: =IF(D3=0,"Compra","Venda") -> Compra | G3: 2347.326 | H3: =ROUND(H2+IF(D3=0,G3,-G3),3) -> 2405.828 | I3: 28 | J3: 5 | K3: 41794 | L3: 19.4105 | M3: 18.249685 | O3: Traspàs a M&G Optimal Income
A4: 1 | B4: 1 | C4: 30 | D4: 1 | E4: =IF(J4>0,"Si","") -> Si | F4: =IF(D4=0,"Compra","Venda") -> Venda | G4: 2404 | H4: =ROUND(H3+IF(D4=0,G4,-G4),3) -> 1.828 | J4: 5 | K4: 41971 | L4: 19.3541 | M4: 18.524505 | O4: Traspàs a DWS Deuschland
A5: 1 | B5: 1 | C5: 92 | D5: 0 | E5: =IF(J5>0,"Si","") -> Si | F5: =IF(D5=0,"Compra","Venda") -> Compra | G5: 2922.36 | H5: =ROUND(H4+IF(D5=0,G5,-G5),3) -> 2924.188 | I5: 91 | J5: 5 | K5: 42202.719 | L5: 15.6417 | M5: 18.3931
A6: 1 | B6: 1 | C6: 100 | D6: 1 | E6: =IF(J6>0,"Si","") -> Si | F6: =IF(D6=0,"Compra","Venda") -> Venda | G6: 2879.243 | H6: =ROUND(H5+IF(D6=0,G6,-G6),3) -> 44.945 | J6: 16 | K6: 42279.464 | L6: 15.6441 | M6: 18.063203 | O6: Traspàs a: DWS AKTIEN STRAT DEUTSCHLAND.
A8: 1 | B8: 2 | C8: 37 | D8: 0 | F8: =IF(D8=0,"Compra","Venda") -> Compra | G8: 76.746 | H8: =G8 -> 76.746 | K8: 41534 | L8: 13.03 | M8: 13.029995 | O8: Compra Inicial.
A9: 1 | B9: 2 | C9: 38 | D9: 1 | F9: =IF(D9=0,"Compra","Venda") -> Venda | G9: 75 | H9: =ROUND(H8+IF(D9=0,G9,-G9),3) -> 1.746 | J9: 6 | K9: 41673 | L9: 13.03 | M9: 12.78 | O9: Traspàs a Dexia
A10: 1 | B10: 2 | C10: 103 | D10: 1 | F10: =IF(D10=0,"Compra","Venda") -> Venda | G10: 1.746 | H10: =ROUND(H9+IF(D10=0,G10,-G10),3) -> 0 | J10: 6 | K10: 42310.831 | L10: 13.03 | M10: 13.648339
A11: 1 | B11: 3 | C11: 1 | D11: 0 | F11: =IF(D11=0,"Compra","Venda") -> Compra | G11: 325.522 | H11: =ROUND(H10+IF(D11=0,G11,-G11),3) -> 325.522 | K11: 41172 | L11: 30.7199 | M11: 30.719859
A12: 1 | B12: 3 | C12: 2 | D12: 0 | F12: =IF(D12=0,"Compra","Venda") -> Compra | G12: 1267.688 | H12: =ROUND(H11+IF(D12=0,G12,-G12),3) -> 1593.21 | K12: 41187 | L12: 31.5535 | M12: 31.55349
A13: 1 | B13: 3 | C13: 3 | D13: 0 | F13: =IF(D13=0,"Compra","Venda") -> Compra | G13: 522.374 | H13: =ROUND(H12+IF(D13=0,G13,-G13),3) -> 2115.584 | K13: 41410 | L13: 38.2868 | M13: 38.286783
A14: 1 | B14: 3 | C14: 4 | D14: 1 | F14: =IF(D14=0,"Compra","Venda") -> Venda | G14: 1415.582 | H14: =ROUND(H13+IF(D14=0,G14,-G14),3) -> 700.002 | K14: 41438 | L14: 31.3618 | M14: 33.983393
A15: 1 | B15: 3 | C15: 5 | D15: 1 | F15: =IF(D15=0,"Compra","Venda") -> Venda | G15: 178 | H15: =ROUND(H14+IF(D15=0,G15,-G15),3) -> 522.002 | K15: 41492 | L15: 31.5676 | M15: 33.896399
A16: 1 | B16: 3 | C16: 6 | D16: 1 | F16: =IF(D16=0,"Compra","Venda") -> Venda | G16: 522.002 | H16: =ROUND(H15+IF(D16=0,G16,-G16),3) -> 0 | K16: 41506 | L16: 38.2868 | M16: 32.470297
A17: 1 | B17: 3 | C17: 41 | D17: 0 | F17: =IF(D17=0,"Compra","Venda") -> Compra | G17: 174.229 | H17: =ROUND(H16+IF(D17=0,G17,-G17),3) -> 174.229 | I17: 40 | J17: 6 | K17: 42047 | L17: 21.5614 | M17: 39.429136 | O17: Traspàs a Asian
A18: 1 | B18: 3 | C18: 95 | D18: 1 | F18: =IF(D18=0,"Compra","Venda") -> Venda | G18: 150 | H18: =ROUND(H17+IF(D18=0,G18,-G18),3) -> 24.229 | J18: 6 | K18: 42207.759 | L18: 21.5614 | M18: 39.577667
A19: 1 | B19: 4 | C19: 11 | D19: 0 | F19: =IF(D19=0,"Compra","Venda") -> Compra | G19: 28.28 | H19: =ROUND(H18+IF(D19=0,G19,-G19),3) -> 52.509 | K19: 41554 | L19: 35.3571 | M19: 35.357143 | O19: Compra inicial.
A20: 1 | B20: 4 | C20: 12 | D20: 0 | F20: =IF(D20=0,"Compra","Venda") -> Compra | G20: 134.86 | H20: =ROUND(H19+IF(D20=0,G20,-G20),3) -> 187.369 | K20: 41565 | L20: 37.0763 | M20: 37.076301
A21: 1 | B21: 4 | C21: 13 | D21: 1 | F21: =IF(D21=0,"Compra","Venda") -> Venda | G21: 160 | H21: =ROUND(H20+IF(D21=0,G21,-G21),3) -> 27.369 | K21: 41639 | L21: 36.7724 | M21: 30.94775
A22: 1 | B22: 5 | C22: 26 | D22: 0 | F22: =IF(D22=0,"Compra","Venda") -> Compra | G22: 249.3471 | H22: =ROUND(H21+IF(D22=0,G22,-G22),3) -> 276.716 | I22: 25 | J22: 11 | K22: 41439 | L22: 182.9832 | M22: 139.70999 | O22: Traspàs total a DWS Deutschland
A23: 1 | B23: 5 | C23: 28 | D23: 1 | F23: =IF(D23=0,"Compra","Venda") -> Venda | G23: 249 | H23: =ROUND(H22+IF(D23=0,G23,-G23),3) -> 27.716 | J23: 1 | K23: 41794 | L23: 182.9832 | M23: 172.04 | O23: Traspàs a M&G Optimal Income
A24: 1 | B24: 5 | C24: 31 | D24: 0 | F24: =IF(D24=0,"Compra","Venda") -> Compra | G24: 264.1805 | I24: 30 | J24: 1 | K24: 41976 | L24: 176.1192 | M24: 168.57001 | O24: Traspàs a DWS Deuschland
A25: 1 | B25: 5 | C25: 91 | D25: 1 | F25: =IF(D25=0,"Compra","Venda") -> Venda | G25: 259.53 | J25: 1 | K25: 42201.719 | L25: 176.1284 | M25: 207.11001
A26: 1 | B26: 6 | C26: 7 | D26: 0 | F26: =IF(D26=0,"Compra","Venda") -> Compra | G26: 24.092 | K26: 41492 | L26: 250.4412 | M26: 250.44123 | O26: Compra inicial.
A27: 1 | B27: 6 | C27: 39 | D27: 0 | F27: =IF(D27=0,"Compra","Venda") -> Compra | G27: 3.144 | I27: 38 | J27: 2 | K27: 41673 | L27: 310.8302 | M27: 304.86641 | O27: Traspàs a Dexia
A28: 1 | B28: 6 | C28: 40 | D28: 1 | F28: =IF(D28=0,"Compra","Venda") -> Venda | G28: 15 | J28: 3 | K28: 42047 | L28: 250.4412 | M28: 457.97993 | O28: Traspàs a Asian
A29: 1 | B29: 6 | C29: 96 | D29: 0 | F29: =IF(D29=0,"Compra","Venda") -> Compra | G29: 10.043 | I29: 95 | J29: 3 | K29: 42208.759 | L29: 322.0362 | M29: 591.12317
A30: 1 | B30: 6 | C30: 104 | D30: 0 | F30: =IF(D30=0,"Compra","Venda") -> Compra | G30: 0.047 | I30: 103 | J30: 2 | K30: 42311.831 | L30: 484.0506 | M30: 507.02128
A31: 1 | B31: 7 | C31: 79 | D31: 0 | F31: =IF(D31=0,"Compra","Venda") -> Compra | G31: 925 | K31: 41711 | L31: 10.825 | M31: 10.825 | N31: 15.06
A32: 1 | B32: 7 | C32: 80 | D32: 1 | F32: =IF(D32=0,"Compra","Venda") -> Venda | G32: 925 | K32: 41717 | L32: 10.825 | M32: 11.05 | N32: 25.32
A33: 1 | B33: 7 | C33: 81 | D33: 0 | F33: =IF(D33=0,"Compra","Venda") -> Compra | G33: 929 | K33: 41830 | L33: 10.74 | M33: 10.74 | N33: 15.06
A34: 1 | B34: 7 | C34: 82 | D34: 1 | F34: =IF(D34=0,"Compra","Venda") -> Venda | G34: 929 | K34: 41877 | L34: 10.74 | M34: 10.98 | N34: 15.09
A35: 1 | B35: 7 | C35: 83 | D35: 0 | F35: =IF(D35=0,"Compra","Venda") -> Compra | G35: 5386 | K35: 41984 | L35: 9.2677 | M35: 9.2677386 | N35: 20.14
A36: 1 | B36: 7 | C36: 84 | D36: 1 | F36: =IF(D36=0,"Compra","Venda") -> Venda | G36: 5386 | K36: 42047 | L36: 9.2677 | M36: 9.045 | N36: 20.03
A37: 1 | B37: 7 | C37: 94 | D37: 0 | F37: =IF(D37=0,"Compra","Venda") -> Compra | G37: 6415 | K37: 42212.556 | L37: 7.794 | M37: 7.794 | N37: 20.15
A38: 1 | B38: 7 | C38: 97 | D38: 1 | F38: =IF(D38=0,"Compra","Venda") -> Venda | G38: 6415 | K38: 42214.283 | L38: 7.794 | M38: 8.19 | N38: 20.4
A39: 1 | B39: 7 | C39: 138 | D39: 5 | F39: =IF(D39=0,"Compra","Venda") -> Venda | G39: 1581 | K39: 42822.417 | L39: 7.591 | M39: 7.591 | N39: 15.15 | O39: ContraSplit. Factor conversor: 3. Preu operació: 7,6.
A40: 1 | B40: 7 | C40: 151 | D40: 0 | F40: =IF(D40=0,"Compra","Venda") -> Compra | G40: 527 | K40: 42822.417 | L40: 22.773 | M40: 22.773 | N40: 15.15 | O40: ContraSplit. Factor conversor: 3. Preu operació: 7,6.
A41: 1 | B41: 7 | C41: 165 | D41: 1 | F41: =IF(D41=0,"Compra","Venda") -> Venda | G41: 527 | K41: 43236.345 | L41: 22.773 | M41: 30.41604 | N41: 27.45
...

Sheet MovId=30
A1: Ordre orig | B1: Ordre flux | C1: ProdId | D1: Id | E1: Mov | F1: Trasp | G1: Mov | H1: Participacions | I1: Part ponderad | J1: Part venudes2 | K1: Part venudes | L1: Part acum | M1: Mov Id Venda | N1: Prod Id Traspas | O1: Data | P1: Preu part orig calc | Q1: Preu Part Origen | R1: Preu Participacio | S1: Descripcio
A2: 3 | B2: 1 | C2: 1 | D2: 30 | E2: 1 | G2: =IF(E2=0,"Compra","Venda") -> Venda | H2: 2404 | I2: =H2*R2 -> 44532.91 | L2: 1.828 | N2: 5 | O2: 41971 | P2: =(K4*P4+K3*P3)/H2 -> 19.354116 | Q2: 19.3541 | R2: 18.524505 | S2: Traspàs a DWS Deuschland
A3: 2 | B3: 2 | C3: 1 | D3: 29 | E3: 0 | F3: =IF(N3>0,"Si","") -> Si | G3: =IF(E3=0,"Compra","Venda") -> Compra | H3: 2347.326 | I3: =H3*R3 -> 42837.96 | J3: =H3 -> 2347.326 | K3: 2345.498 | L3: 2405.828 | M3: 28 | N3: 5 | O3: 41794 | P3: =H6*P6/H3 -> 19.410506 | Q3: 19.4105 | R3: 18.249685 | S3: Traspàs a M&G Optimal Income
A4: 1 | B4: 3 | C4: 1 | D4: 27 | E4: 0 | F4: =IF(N4>0,"Si","") | G4: =IF(E4=0,"Compra","Venda") -> Compra | H4: 58.502 | I4: =H4*R4 -> 999.99 | J4: =H2-H3 -> 56.674 | K4: 58.502 | L4: 58.502 | O4: 41521 | P4: =R4 -> 17.093262 | Q4: 17.0933 | R4: 17.093262 | S4: Compra inicial.
A5: 4 | B5: 4
A6: 6 | B6: 5 | C6: 5 | D6: 28 | E6: 1 | G6: =IF(E6=0,"Compra","Venda") -> Venda | H6: 249 | I6: =H6*R6 -> 42837.96 | L6: 0.347 | N6: 1 | O6: 41794 | P6: =(K7*P7)/H6 -> 182.98308 | Q6: 182.9832 | R6: 172.04 | S6: Traspàs a M&G Optimal Income
A7: 5 | B7: 6 | C7: 5 | D7: 26 | E7: 0 | F7: =IF(N7>0,"Si","") -> Si | G7: =IF(E7=0,"Compra","Venda") -> Compra | H7: 249.3471 | I7: =H7*R7 -> 34836.28 | J7: =H6 -> 249 | K7: 249 | L7: 249.3471 | M7: 25 | N7: 11 | O7: 41439 | P7: =H9*P9/H7 -> 182.98308 | Q7: 182.9832 | R7: 139.70999 | S7: Traspàs total a DWS Deutschland
A8: 10 | B8: 7 | F8: =IF(N8>0,"Si","")
A9: 14 | B9: 8 | C9: 11 | D9: 25 | E9: 1 | G9: =IF(E9=0,"Compra","Venda") -> Venda | H9: 1838.3261 | I9: =H9*R9 -> 34836.28 | L9: 0 | N9: 5 | O9: 41439 | P9: =(K12*P12+K11*P11+K10*P10)/H9 -> 24.819481 | Q9: 24.8195 | R9: 18.95 | S9: Traspàs total a DWS Deutschland
A10: 13 | B10: 9 | C10: 11 | D10: 24 | E10: 0 | F10: =IF(N10>0,"Si","") -> Si | G10: =IF(E10=0,"Compra","Venda") -> Compra | H10: 280.07 | I10: =H10*R10 -> 5511.77 | J10: =H10 -> 280.07 | K10: 280.07 | L10: 1838.326 | M10: 23 | N10: 10 | O10: 41383 | P10: =H14*P14/H10 -> 55.794301 | Q10: 55.7942 | R10: 19.679973
A11: 12 | B11: 10 | C11: 11 | D11: 17 | E11: 0 | F11: =IF(N11>0,"Si","") | G11: =IF(E11=0,"Compra","Venda") -> Compra | H11: 1010.611 | I11: =H11*R11 -> 19999.99 | J11: =H11-H9/H7*L6 -> 1008.0527 | K11: 1010.611 | L11: 1558.256 | O11: 41377 | P11: =R11 -> 19.789998 | Q11: 19.79 | R11: 19.789998
A12: 11 | B12: 11 | C12: 11 | D12: 16 | E12: 0 | F12: =IF(N12>0,"Si","") | G12: =IF(E12=0,"Compra","Venda") -> Compra | H12: 547.64513 | I12: =H12*R12 -> 10000 | J12: =H12 -> 547.64513 | K12: 547.64513 | L12: 547.64513 | O12: 41166 | P12: =R12 -> 18.26 | Q12: 18.26 | R12: 18.26 | S12: Compra inicial.
A13: 7 | B13: 12 | F13: =IF(N13>0,"Si","")
A14: 9 | B14: 13 | C14: 10 | D14: 23 | E14: 1 | G14: =IF(E14=0,"Compra","Venda") -> Venda | H14: 679.64 | I14: =H14*R14 -> 5511.77 | L14: 0 | N14: 11 | O14: 41383 | P14: =P15 -> 22.99204 | Q14: 22.992 | R14: 8.1098376 | S14: Traspàs a Templeton Total return
A15: 8 | B15: 14 | C15: 10 | D15: 15 | E15: 0 | F15: =IF(N15>0,"Si","") | G15: =IF(E15=0,"Compra","Venda") -> Compra | H15: 679.64 | I15: =H15*R15 -> 15626.31 | J15: =H15 -> 679.64 | K15: 679.64 | L15: 679.64 | O15: 36841 | P15: =R15 -> 22.99204 | Q15: 22.992 | R15: 22.99204 | S15: Data ficticia, son fons que provenien d'Argentaria.
F17: =IF(N16>0,"Si","") | G17: =H2*Q2+L2*Q3 -> 46562.739 | H17: Cost total origen. A partir de "Preu Part Origen" | S17: Venda, inici flux
S18: Vendes
G19: =K4*R4+K12*R12+K11*R11+K15*R15 -> 46626.29 | H19: Cost total origen. A partir de les compres originals. | S19: Compres
G20: =G19-G17 -> 63.551206 | H20: Diferència | S20: Compres Origen
S21: S'han venut parcialment
G22: =J4*R4+J12*R12+J11*R11+J15*R15 -> 46544.415 | H22: Cost total origen. A partir de les compres originals amb "Part venudes2".
G23: =G22-G17 -> -18.323591 | H23: Diferència
G26: Fons A comprat 10 part dia 1
G27: Fons B comprat 10 part dia 2
G28: Traspàs 5 part de fons B a fons C dia 3
G29: Traspàs 5 part de fons A a fons C dia 4
G30: Venda 5 part de fons C. Haurien de ser les part del fons A, però en les compres del fons C és més antic el traspas des del fons B.

Sheet MovId=30 (2)
A1: Ordre orig | B1: Ordre flux | C1: ProdId | D1: Id | E1: Mov | F1: Trasp | G1: Mov | H1: Participacions | I1: Part venudes | J1: Mov Id Venda | K1: Prod Id Traspas | L1: Data | M1: Preu Part Origen | N1: Preu Participacio | O1: Descripcio
A2: 3 | B2: 1 | C2: 1 | D2: 30 | E2: 1 | G2: =IF(E2=0,"Compra","Venda") -> Venda | H2: 2404 | I2: =H2 -> 2404 | K2: 5 | L2: 41971 | M2: 19.3541 | N2: 18.524505 | O2: Traspàs a DWS Deuschland
A3: 2 | B3: 2 | C3: 1 | D3: 29 | E3: 0 | F3: =IF(K3>0,"Si","") -> Si | G3: =IF(E3=0,"Compra","Venda") -> Compra | H3: 2347.326 | I3: =H3 -> 2347.326 | J3: 28 | K3: 5 | L3: 41794 | M3: 19.4105 | N3: 18.249685 | O3: Traspàs a M&G Optimal Income
A4: 1 | B4: 3 | C4: 1 | D4: 27 | E4: 0 | F4: =IF(K4>0,"Si","") | G4: =IF(E4=0,"Compra","Venda") -> Compra | H4: 58.502 | I4: =I2-I3 -> 56.674 | L4: 41521 | M4: 17.0933 | N4: 17.093262 | O4: Compra inicial.
A5: 4 | B5: 4
A6: 6 | B6: 5 | C6: 5 | D6: 28 | E6: 1 | G6: =IF(E6=0,"Compra","Venda") -> Venda | H6: 249 | I6: =I3/H3*H6 -> 249 | K6: 1 | L6: 41794 | M6: 182.9832 | N6: 172.04 | O6: Traspàs a M&G Optimal Income
A7: 5 | B7: 6 | C7: 5 | D7: 26 | E7: 0 | F7: =IF(K7>0,"Si","") -> Si | G7: =IF(E7=0,"Compra","Venda") -> Compra | H7: 249.3471 | I7: =I6 -> 249 | J7: 25 | K7: 11 | L7: 41439 | M7: 182.9832 | N7: 139.70999 | O7: Traspàs total a DWS Deutschland
A8: 10 | B8: 7 | F8: =IF(K8>0,"Si","")
A9: 14 | B9: 8 | C9: 11 | D9: 25 | E9: 1 | G9: =IF(E9=0,"Compra","Venda") -> Venda | H9: 1838.3261 | I9: =I7/H7*H9 -> 1835.7671 | K9: 5 | L9: 41439 | M9: 24.8195 | N9: 18.95 | O9: Traspàs total a DWS Deutschland
A10: 13 | B10: 9 | C10: 11 | D10: 24 | E10: 0 | F10: =IF(K10>0,"Si","") -> Si | G10: =IF(E10=0,"Compra","Venda") -> Compra | H10: 280.07 | I10: =H10 -> 280.07 | J10: 23 | K10: 10 | L10: 41383 | M10: 55.7942 | N10: 19.679973
A11: 12 | B11: 10 | C11: 11 | D11: 17 | E11: 0 | F11: =IF(K11>0,"Si","") | G11: =IF(E11=0,"Compra","Venda") -> Compra | H11: 1010.611 | I11: =I9-I10-I12 -> 1008.052 | L11: 41377 | M11: 19.79 | N11: 19.789998
A12: 11 | B12: 11 | C12: 11 | D12: 16 | E12: 0 | F12: =IF(K12>0,"Si","") | G12: =IF(E12=0,"Compra","Venda") -> Compra | H12: 547.64513 | I12: =H12 -> 547.64513 | L12: 41166 | M12: 18.26 | N12: 18.26 | O12: Compra inicial.
A13: 7 | B13: 12 | F13: =IF(K13>0,"Si","")
A14: 9 | B14: 13 | C14: 10 | D14: 23 | E14: 1 | G14: =IF(E14=0,"Compra","Venda") -> Venda | H14: 679.64 | I14: =I10/H10*H14 -> 679.64 | K14: 11 | L14: 41383 | M14: 22.992 | N14: 8.1098376 | O14: Traspàs a Templeton Total return
A15: 8 | B15: 14 | C15: 10 | D15: 15 | E15: 0 | F15: =IF(K15>0,"Si","") | G15: =IF(E15=0,"Compra","Venda") -> Compra | H15: 679.64 | I15: =I14 -> 679.64 | L15: 36841 | M15: 22.992 | N15: 22.99204 | O15: Data ficticia, son fons que provenien d'Argentaria.
F17: =IF(K16>0,"Si","") | G17: =H2*M2 -> 46527.256 | H17: Cost total origen. A partir de "Preu Part Origen" | O17: Venda, inici flux
G18: =I15*N15+I12*N12+I11*N11+I4*N4 -> 46544.401 | H18: Cost total origen. A partir de les compres originals. | O18: Vendes
G19: =G18-G17 -> 17.144213 | H19: Diferència | O19: Compres
O20: Compres Origen
O21: Moviment parcial
G23: Fons A comprat 10 part dia 1
G24: Fons B comprat 10 part dia 2
G25: Traspàs 5 part de fons B a fons C dia 3
G26: Traspàs 5 part de fons A a fons C dia 4
G27: Venda 5 part de fons C. Haurien de ser les part del fons A, però en les compres del fons C és més antic el traspas des del fons B.

Sheet NovaTaulaDesgloç
A1: Preu Participacio | B1: Prod Id | C1: Id | D1: Mov Id | E1: Trasp | F1: Ref. Id. | G1: Participacions | H1: 1 | I1: Mov Id | J1: Ref | K1: Part. restants | L1: Part. Restants orig | M1: 2 | N1: Mov Id | O1: Ref Venda | P1: Part. restants | Q1: Part. Restants orig
A2: 10 | B2: 1 | C2: 1 | D2: Compra | E2: No | G2: 2 | I2: 1 | K2: 2 | L2: 2 | N2: 1 | O2: 3 | P2: 0 | Q2: 0
A3: 15 | B3: 1 | C3: 2 | D3: Compra | E3: No | G3: 10 | I3: 2 | K3: 10 | L3: 10 | N3: 2 | O3: 3 | P3: 4 | Q3: 4
A4: 12 | B4: 1 | C4: 3 | D4: Venda | E4: Si | F4: =C7 -> 5 | G4: 8
A6: 4 | B6: 2 | C6: 4 | D6: Compra | E6: No | G6: 5 | I6: 4 | K6: 5 | L6: =G6 -> 5 | P6: 3
A7: =G4*A4/G7 -> 9.6 | B7: 2 | C7: 5 | D7: Compra | E7: Si | F7: =C4 -> 3 | G7: 10
I8: 1 | J8: 5 | K8: =G7/G4*L8 -> 2.5 | L8: =G2 -> 2 | N8: 1 | O8: 7 | P8: 0 | Q8: 0
I9: 2 | J9: 5 | K9: =G7/G4*L9 -> 7.5 | L9: =G4-L8 -> 6 | N9: 2 | O9: 7 | P9: =K9-(G10-K8) -> 2 | Q9: =L9/K9*P9 -> 1.6
A10: 7 | B10: 2 | C10: 6 | D10: Compra | E10: No | G10: 8 | I10: 6 | K10: 8 | L10: =G10 -> 8
A11: 10 | B11: 2 | C11: 7 | D11: Venda | E11: Si | F11: =C13 -> 8 | G11: 8
A13: =A11*G11/G13 -> 1.6 | B13: 3 | C13: 8 | D13: Compra | E13: Si | F13: =C11 -> 7 | G13: 50
I14: 1 | J14: 5 | K14: =G13/G10*K8 -> 15.625 | L14: 2
I15: 2 | J15: 5 | K15: =G13/G10*(G10-K8) -> 34.375 | L15: =L9-Q9 -> 4.4
K16: =SUM(K14:K15) -> 50

Sheet Sheet5
A1: Data | B1: Id | C1: Usu | D1: Prod | E1: TipusMov | F1: Pro trasp | G1: MovRefVenda | H1: Part | I1: Preu U Orig | J1: Preu U
A2: 2013-09-04 00:00:00.000 | B2: 27 | C2: 1 | D2: 1 | E2: C | H2: 58.502 | I2: 17.0933 | J2: 17.093262 | M2: Compra inicial.
A3: 2014-12-03 00:00:00.000 | B3: 31 | C3: 1 | D3: 5 | E3: CT | F3: 1 | G3: 30 | H3: 264.1805 | I3: 176.1192 | J3: 168.57001 | M3: Traspàs a DWS Deuschland
A4: 2014-11-28 00:00:00.000 | B4: 30 | C4: 1 | D4: 1 | E4: VT | F4: 5 | H4: 2404 | I4: 19.3541 | J4: 18.524505 | M4: Traspàs a DWS Deuschland
A5: 2014-06-04 00:00:01.000 | B5: 29 | C5: 1 | D5: 1 | E5: CT | F5: 5 | G5: 28 | H5: 2347.326 | I5: 19.4105 | J5: 18.249685 | M5: Traspàs a M&G Optimal Income
A6: 2013-06-14 00:00:01.000 | B6: 26 | C6: 1 | D6: 5 | E6: CT | F6: 11 | G6: 25 | H6: 249.3471 | I6: 182.9832 | J6: 139.70999 | M6: Traspàs total a DWS Deutschland
A7: 2014-06-04 00:00:00.000 | B7: 28 | C7: 1 | D7: 5 | E7: VT | F7: 1 | H7: 249 | I7: 182.9832 | J7: 172.04 | M7: Traspàs a M&G Optimal Income
A8: 2015-07-16 17:15:31.000 | B8: 91 | C8: 1 | D8: 5 | E8: VT | F8: 1 | H8: 259.53 | I8: 176.1284 | J8: 207.11001 | M8: NULL
A9: 2000-11-11 00:00:00.000 | B9: 15 | C9: 1 | D9: 10 | E9: C | H9: 679.64 | I9: 22.992 | J9: 22.99204 | M9: Data ficticia, son fons que provenien d'Argentaria.
A10: 2013-04-19 00:00:00.000 | B10: 23 | C10: 1 | D10: 10 | E10: VT | F10: 11 | H10: 679.64 | I10: 22.992 | J10: 8.1098376 | M10: Traspàs a Templeton Total return
A11: 2012-09-14 00:00:00.000 | B11: 16 | C11: 1 | D11: 11 | E11: C | H11: 547.64513 | I11: 18.26 | J11: 18.26 | M11: Compra inicial.
A12: 2013-04-13 00:00:00.000 | B12: 17 | C12: 1 | D12: 11 | E12: C | H12: 1010.611 | I12: 19.79 | J12: 19.789998 | M12: NULL
A13: 2013-04-19 00:00:01.000 | B13: 24 | C13: 1 | D13: 11 | E13: CT | F13: 10 | G13: 23 | H13: 280.07 | I13: 55.7942 | J13: 19.679973 | M13: qwe
A14: 2013-06-14 00:00:00.000 | B14: 25 | C14: 1 | D14: 11 | E14: VT | F14: 5 | H14: 1838.3261 | I14: 24.8195 | J14: 18.95 | M14: Traspàs total a DWS Deutschland

Sheet Sheet4
A1: Nom | B1: Id | C1: Ord | D1: Mov | E1: Data | F1: Part | G1: Preu U | H1: Brut | I1: Net | J1: Preu U Or | K1: Part Op | L1: Resta P
A2: Deutch | B2: 91 | C2: 1 | D2: Traspàs V | E2: 42201 | F2: 259.53 | G2: 207.11 | H2: 53751.26 | I2: 53751.26 | J2: 176.1284 | K2: =F2 -> 259.53 | M2: =J2*K2 -> 45710.604
A3: Deutch | B3: 26 | C3: 2 | D3: Traspàs C | E3: 41439 | F3: 249.3471 | G3: 139.71 | H3: 34836.28 | J3: 182.9832 | K3: =Sheet2!E3-Sheet2!E4 -> 0.3471 | L3: =F3-K3 -> 249 | M3: =J3*K3 -> 63.513469
A4: Total Return | B4: 25 | C4: 3 | D4: Traspàs V | E4: 41439 | F4: 1838.3261 | G4: 18.95 | H4: 34836.28 | J4: 24.8195 | K4: =K3/F3*F4 -> 2.5590151 | M4: =J4*K4 -> 63.513475
A5: Total Return | B5: 24 | C5: 4 | D5: Traspàs C | E5: 41383 | F5: 280.07 | G5: 19.68 | J5: 55.7942 | K5: =K4 -> 2.5590151 | L5: =F5-K5 -> 277.51098 | M5: =J5*K5 -> 142.7782
A6: Bolsa Tecnología y Telecomunicaciones FI | B6: 23 | C6: 5 | D6: Traspàs V | E6: 41383 | F6: 679.64 | G6: 8.11 | H6: 5511.77 | J6: 22.992 | K6: =K5/F5*F6 -> 6.2099083 | M6: =J6*K6 -> 142.77821
A7: Bolsa Tecnología y Telecomunicaciones FI | B7: 15 | C7: 6 | D7: Compra | E7: 36841 | F7: 679.64 | G7: 22.992 | H7: 15626.31 | J7: 22.992 | K7: =K6 -> 6.2099083 | L7: =F7-K7 -> 673.43009 | M7: =J7*K7 -> 142.77821
A8: Deutch | B8: 31 | C8: 7 | D8: Traspàs C | E8: 41976 | F8: 264.1805 | G8: 168.57 | J8: 176.1192 | K8: =F2-K3 -> 259.1829 | L8: =F8-K8 -> 4.9976
A9: Optimal Income | B9: 30 | C9: 8 | D9: Traspàs V | E9: 41971 | F9: 2404 | G9: 18.525 | H9: 44532.91 | J9: 19.3541 | K9: =K8/F8*F9 -> 2358.5226
A10: Optimal Income | B10: 27 | C10: 9 | D10: Compra | E10: 41521 | F10: 58.502 | G10: 17.093 | H10: 999.99 | J10: 17.0933 | K10: =F10 -> 58.502 | L10: =F10-K10 -> 0
A11: Optimal Income | B11: 29 | C11: 10 | D11: Traspàs C | E11: 41794 | F11: 2347.326 | G11: 18.25 | H11: 42837.96 | J11: 19.4105 | K11: =K9-K10 -> 2300.0206 | L11: =F11-K11 -> 47.305355
A12: Deutch | B12: 28 | C12: 11 | D12: Traspàs V | E12: 41794 | F12: 249 | G12: 172.04 | J12: 182.9832 | K12: =K11/F11*F12 -> 243.98194
A13: Deutch | B13: 26 | C13: 12 | D13: Traspàs C | E13: 41439 | F13: 249.3471 | G13: 139.71 | J13: 182.9832 | K13: =K12 -> 243.98194 | L13: =F13-K13 -> 5.3651646
A14: Total Return | B14: 25 | C14: 13 | D14: Traspàs V | E14: 41439 | F14: 1838.3261 | G14: 18.95 | J14: 24.8195 | K14: =K13/F13*F14 -> 1798.7711
A15: Total Return | B15: 16 | C15: 14 | D15: Compra | E15: 41166 | F15: 547.6451 | G15: 18.26 | H15: 10000 | J15: 18.26 | K15: =F15 -> 547.6451 | L15: =F15-K15 -> 0
A16: Total Return | B16: 17 | C16: 15 | D16: Compra | E16: 41377 | F16: 1010.611 | G16: 19.79 | H16: 19999.99 | J16: 19.79 | K16: =F16 -> 1010.611 | L16: =F16-K16 -> 0
A17: Total Return | B17: 24 | C17: 16 | D17: Traspàs C | E17: 41383 | F17: 280.07 | G17: 19.68 | H17: 34836.28 | J17: 55.7942 | K17: =+K14-K15-K16 -> 240.51501 | L17: =F17-K17 -> 39.55499
A18: Bolsa Tecnología y Telecomunicaciones FI | B18: 23 | C18: 17 | D18: Traspàs V | E18: 41383 | F18: 679.64 | G18: 8.11 | J18: 22.992 | K18: =K17/F17*F18 -> 583.65273
A19: Bolsa Tecnología y Telecomunicaciones FI | B19: 15 | C19: 18 | D19: Compra | E19: 36841 | F19: 679.64 | G19: 22.992 | H19: 15626.31 | J19: 22.992 | K19: =K18 -> 583.65273 | L19: =F19-K19 -> 95.987265
H20: 5511.77
F21: =A7 -> Bolsa Tecnología y Telecomunicaciones FI | G21: =G7 -> 22.992 | H21: 5511.77 | K21: =+K7 -> 6.2099083 | L21: =G21*K21 -> 142.77821
F22: =A10 -> Optimal Income | G22: =G10 -> 17.093 | H22: 5514.77 | K22: =+K10 -> 58.502 | L22: =G22*K22 -> 999.97469
F23: =A15 -> Total Return | G23: =G15 -> 18.26 | H23: 5519.77 | K23: =+K15 -> 547.6451 | L23: =G23*K23 -> 9999.9995
F24: =A16 -> Total Return | G24: =G16 -> 19.79 | H24: 5520.77 | K24: =+K16 -> 1010.611 | L24: =G24*K24 -> 19999.992
F25: =A19 -> Bolsa Tecnología y Telecomunicaciones FI | G25: =G19 -> 22.992 | H25: 5523.77 | K25: =+K19 -> 583.65273 | L25: =G25*K25 -> 13419.344
L26: =SUM(L21:L25) -> 44562.088 | M26: =L26/F2 -> 171.70303

Sheet Sheet3
A1: Nom | B1: Id | C1: Ord | D1: Mov | E1: Data | F1: Part | G1: Preu U | H1: Brut | I1: Net | J1: Ref | K1: Num Part | L1: Part Op
A2: Deutch | B2: 91 | C2: 1 | D2: Traspàs V | E2: 42201 | F2: 259.53 | G2: 207.11 | H2: 53751.26 | I2: 53751.26 | K2: =L2 -> 259.53 | L2: =F2 -> 259.53 | M2: =K2-L2 -> 0
A3: Deutch | B3: 26 | C3: 2 | D3: Traspàs C | E3: 41439 | F3: 249.3471 | G3: 139.71 | H3: 34836.28 | I3: 34836.28 | J3: 25 | L3: =F3-Sheet2!E4 -> 0.3471
A4: Total Return | B4: 25 | C4: 3 | D4: Traspàs V | E4: 41439 | F4: 1838.3261 | G4: 18.95 | H4: 34836.28 | I4: 34836.28 | L4: =L3/F3*F4 -> 2.5590151
A5: Total Return | B5: 24 | C5: 4 | D5: Traspàs C | E5: 41383 | F5: 280.07 | G5: 19.68 | H5: 5511.77 | I5: 5511.77 | J5: 23 | K5: =Sheet2!K7*F4 -> 2.5590151 | L5: =L4 -> 2.5590151
A6: Bolsa Tecnología y Telecomunicaciones FI | B6: 23 | C6: 5 | D6: Traspàs V | E6: 41383 | F6: 679.64 | G6: 8.11 | H6: 5511.77 | I6: 5511.77 | L6: =L5/F5*F6 -> 6.2099083
A7: Bolsa Tecnología y Telecomunicaciones FI | B7: 15 | C7: 6 | D7: Compra | E7: 36841 | F7: 679.64 | G7: 22.992 | H7: 15626.31 | I7: 15626.31 | K7: =K5/F5*F7 -> 6.2099083 | L7: =L6 -> 6.2099083 | M7: =K7-L7 -> 0
A8: Deutch | B8: 31 | C8: 7 | D8: Traspàs C | E8: 41976 | F8: 264.1805 | G8: 168.57 | H8: 44532.91 | I8: 44532.91 | J8: 30 | K8: =F8-(Sheet2!E3-Sheet2!E4+Sheet2!E6-Sheet2!E7) -> 259.1829 | L8: =F2-L3 -> 259.1829
A9: Optimal Income | B9: 30 | C9: 8 | D9: Traspàs V | E9: 41971 | F9: 2404 | G9: 18.525 | H9: 44532.91 | I9: 44532.91 | L9: =L8/F8*F9 -> 2358.5226
A10: Optimal Income | B10: 27 | C10: 9 | D10: Compra | E10: 41521 | F10: 58.502 | G10: 17.093 | H10: 999.99 | I10: 999.99 | K10: =F10 -> 58.502 | L10: =F10 -> 58.502 | M10: =K10-L10 -> 0
A11: Optimal Income | B11: 29 | C11: 10 | D11: Traspàs C | E11: 41794 | F11: 2347.326 | G11: 18.25 | H11: 42837.96 | I11: 42837.96 | J11: 28 | K11: =F11-(Sheet2!E9+Sheet2!E10-Sheet2!E11) -> 2345.498 | L11: =L9-L10 -> 2300.0206
A12: Deutch | B12: 28 | C12: 11 | D12: Traspàs V | E12: 41794 | F12: 249 | G12: 172.04 | H12: 42837.96 | I12: 42837.96 | L12: =L11/F11*F12 -> 243.98194
A13: Deutch | B13: 26 | C13: 12 | D13: Traspàs C | E13: 41439 | F13: 249.3471 | G13: 139.71 | H13: 34836.28 | I13: 34836.28 | J13: 25 | K13: =Sheet2!K4*F13 -> 249 | L13: =L12 -> 243.98194
A14: Total Return | B14: 25 | C14: 13 | D14: Traspàs V | E14: 41439 | F14: 1838.3261 | G14: 18.95 | H14: 34836.28 | I14: 34836.28 | L14: =L13/F13*F14 -> 1798.7711
A15: Total Return | B15: 16 | C15: 14 | D15: Compra | E15: 41166 | F15: 547.6451 | G15: 18.26 | H15: 10000 | I15: 10000 | K15: =F15 -> 547.6451 | L15: =F15 -> 547.6451 | M15: =K15-L15 -> 0
A16: Total Return | B16: 17 | C16: 15 | D16: Compra | E16: 41377 | F16: 1010.611 | G16: 19.79 | H16: 19999.99 | I16: 19999.99 | K16: =F16 -> 1010.611 | L16: =F16 -> 1010.611 | M16: =K16-L16 -> 0
A17: Total Return | B17: 24 | C17: 16 | D17: Traspàs C | E17: 41383 | F17: 280.07 | G17: 19.68 | H17: 5511.77 | I17: 5511.77 | J17: 23 | K17: =F17-K5 -> 277.51098 | L17: =L14-L15-L16 -> 240.51501
A18: Bolsa Tecnología y Telecomunicaciones FI | B18: 23 | C18: 17 | D18: Traspàs V | E18: 41383 | F18: 679.64 | G18: 8.11 | H18: 5511.77 | I18: 5511.77 | L18: =L17/F17*F18 -> 583.65273
A19: Bolsa Tecnología y Telecomunicaciones FI | B19: 15 | C19: 18 | D19: Compra | E19: 36841 | F19: 679.64 | G19: 22.992 | H19: 15626.31 | I19: 15626.31 | K19: =K17/F17*F19 -> 673.43009 | L19: =L18 -> 583.65273 | M19: =K19-L19 -> 89.777357
A21: =A7 -> Bolsa Tecnología y Telecomunicaciones FI | B21: =B7 -> 15 | C21: =C7 -> 6 | D21: =D7 -> Compra | E21: =E7 -> 36841 | G21: =F7 -> 679.64 | H21: =G7 -> 22.992 | I21: =H7 -> 15626.31 | J21: =I7 -> 15626.31 | L21: =L7 -> 6.2099083 | M21: =L21*H21 -> 142.77821
A22: =A10 -> Optimal Income | B22: =B10 -> 27 | C22: =C10 -> 9 | D22: =D10 -> Compra | E22: =E10 -> 41521 | G22: =F10 -> 58.502 | H22: =G10 -> 17.093 | I22: =H10 -> 999.99 | J22: =I10 -> 999.99 | L22: =L10 -> 58.502 | M22: =L22*H22 -> 999.97469
A23: =A15 -> Total Return | B23: =B15 -> 16 | C23: =C15 -> 14 | D23: =D15 -> Compra | E23: =E15 -> 41166 | G23: =F15 -> 547.6451 | H23: =G15 -> 18.26 | I23: =H15 -> 10000 | J23: =I15 -> 10000 | L23: =L15 -> 547.6451 | M23: =L23*H23 -> 9999.9995
A24: =A16 -> Total Return | B24: =B16 -> 17 | C24: =C16 -> 15 | D24: =D16 -> Compra | E24: =E16 -> 41377 | G24: =F16 -> 1010.611 | H24: =G16 -> 19.79 | I24: =H16 -> 19999.99 | J24: =I16 -> 19999.99 | L24: =L16 -> 1010.611 | M24: =L24*H24 -> 19999.992
A25: =A19 -> Bolsa Tecnología y Telecomunicaciones FI | B25: =B19 -> 15 | C25: =C19 -> 18 | D25: =D19 -> Compra | E25: =E19 -> 36841 | G25: =F19 -> 679.64 | H25: =G19 -> 22.992 | I25: =H19 -> 15626.31 | J25: =I19 -> 15626.31 | L25: =K19 -> 673.43009 | M25: =L25*H25 -> 15483.505
M26: =SUM(M21:M25) -> 46626.249 | N26: =M26/(F2+5) -> 176.26072
B27: Id: 15 | C27: Part: 0 | M27: =(F2+5)*N27 -> 46591.246 | N27: 176.1284
B28: Id: 17 | C28: Part: 1010.611 | M28: =+M26-M27 -> 35.00313 | N28: =+N26-N27 -> 0.13232197
B29: Id: 16 | C29: Part: 547.645126
B30: Id: 27 | C30: Part: 58.502 | M30: NumPart
B31: Id: 16 | C31: Part: 2.55901511721861 | L31: 16 | M31: 2.5590151
L32: 16 | M32: 1798.7711
B33: Id: 16 | D33: Part: 2.55901511721861 | L33: 17 | M33: 1798.7711
B34: Id: 27 | D34: Part: 58.502 | L34: 15 | M34: 583.65273
B35: Id: 16 | D35: Part: 545.086110882781
B36: Id: 17 | D36: Part: 1010.611
B37: Id: 15 | D37: Part: 583.652733356989
B39: Id: 16 | D39: Part: 2.55901511721861
B40: Id: 27 | D40: Part: 58.502
B41: Id: 16 | D41: Part: 545.086110882781
B42: Id: 17 | D42: Part: 1010.611
...

Sheet Sheet2
A1: Id | B1: Ord | C1: Mov | D1: Data | E1: Part | F1: Preu U | G1: Brut | H1: Net | I1: Preu U Ori | J1: Ref | L1: De | M1: A
A2: Deutch
A3: 26 | B3: 2;12 | C3: Traspàs C | D3: 41439 | E3: 249.3471 | F3: 139.71 | G3: 34836.28 | H3: 34836.28 | I3: 182.9832 | J3: 25 | L3: Total Return N Acc €-H1
A4: 28 | B4: 11 | C4: Traspàs V | D4: 41794 | E4: 249 | F4: 172.04 | G4: 42837.96 | H4: 42837.96 | I4: 182.9832 | K4: =E4/E3 -> 0.99860796 | M4: Optimal Income A-H Grs Acc Hdg EUR
A6: 31 | B6: 7 | C6: Traspàs C | D6: 41976 | E6: 264.1805 | F6: 168.57 | G6: 44532.91 | H6: 44532.91 | I6: 176.1192 | J6: 30 | L6: Optimal Income A-H Grs Acc Hdg EUR
A7: 91 | B7: 1 | C7: Traspàs V | D7: 42201 | E7: 259.53 | F7: 207.11 | G7: 53751.26 | H7: 53751.26 | I7: 176.1284 | K7: =(E3-E4)/E3 -> 0.0013920354 | M7: Optimal Income A-H Grs Acc Hdg EUR
A8: Optimal Income
A9: 27 | B9: 9 | C9: Compra | D9: 41521 | E9: 58.502 | F9: 17.093 | G9: 999.99 | H9: 999.99 | I9: 17.0933
A10: 29 | B10: 10 | C10: Traspàs C | D10: 41794 | E10: 2347.326 | F10: 18.25 | G10: 42837.96 | H10: 42837.96 | I10: 19.4105 | J10: 28 | L10: Deutschland
A11: 30 | B11: 8 | C11: Traspàs V | D11: 41971 | E11: 2404 | F11: 18.525 | G11: 44532.91 | H11: 44532.91 | I11: 19.3541 | K11: 1 | M11: Deutschland
A12: Total Return
A13: 16 | B13: 14 | C13: Compra | D13: 41166 | E13: 547.6451 | F13: 18.26 | G13: 10000 | H13: 10000 | I13: 18.26
A14: 17 | B14: 15 | C14: Compra | D14: 41377 | E14: 1010.611 | F14: 19.79 | G14: 19999.99 | H14: 19999.99 | I14: 19.79
A15: 24 | B15: 4;16 | C15: Traspàs C | D15: 41383 | E15: 280.07 | F15: 19.68 | G15: 5511.77 | H15: 5511.77 | I15: 55.7942 | J15: 23 | K15: =E15*K4 -> 279.68013 | L15: Bolsa Tecnología y Telecomunicaciones FI
A16: 25 | B16: 3;13 | C16: Traspàs V | D16: 41439 | E16: 1838.3261 | F16: 18.95 | G16: 34836.28 | H16: 34836.28 | I16: 24.8195 | K16: 1 | M16: Deutschland
A17: Bolsa Tecnología y Telecomunicaciones FI
A18: 15 | B18: 6;18 | C18: Compra | D18: 36841 | E18: 679.64 | F18: 22.992 | G18: 15626.31 | H18: 15626.31 | I18: 22.992
A19: 23 | B19: 5;17 | C19: Traspàs V | D19: 41383 | E19: 679.64 | F19: 8.11 | G19: 5511.77 | H19: 5511.77 | I19: 22.992 | K19: 1 | L19: Total Return N Acc €-H1 | M19: Traspàs a Templeton Total return
A22: Id:16 | C22: Part:2.55901511721861
A23: Id:27 | C23: Part:58.502
A24: Id:16 | C24: Part:547.645126
A25: Id:17 | C25: Part:1010.611
A26: Id:15 | C26: Part:583.652733356989
A28: Id: 16 | C28: Part: 2.55901511721861
A29: Id: 27 | C29: Part: 58.502
A30: Id: 16 | C30: Part: 545.086110882781
A31: Id: 17 | C31: Part: 1010.611
A32: Id: 15 | C32: Part: 583.652733356989
A34: Id: 16 | C34: Part: 2.55901511721861
A35: Id: 27 | C35: Part: 58.502
... A38: Id: 15 | C38: Part: 583.652733356989

Sheet Sheet1
A1: Id | B1: Mov | C1: Data | D1: Part | E1: Preu U | F1: Brut | G1: Net | H1: Ref | L1: De | M1: A
A2: Asian Smaller
A3: 1 | B3: Compra | C3: 41172 | D3: 325.522 | E3: 30.72 | F3: 9999.99 | G3: 9999.99 | H3: 1
A4: 2 | B4: Compra | C4: 41187 | D4: 1267.688 | E4: 31.553 | F4: 39999.98 | G4: 39999.98 | H4: 1
A5: 3 | B5: Compra | C5: 41410 | D5: 522.374 | E5: 38.287 | F5: 20000.02 | G5: 20000.02 | H5: 1
A6: 4 | B6: Venda | C6: 41438 | D6: 1415.582 | E6: 33.983 | F6: 48106.28 | G6: 48106.28 | H6: 1
A7: 5 | B7: Venda | C7: 41492 | D7: 178 | E7: 33.896 | F7: 6033.56 | G7: 6033.56 | H7: 1
A8: 6 | B8: Venda | C8: 41506 | D8: 522.002 | E8: 32.47 | F8: 16949.56 | G8: 16949.56 | H8: 1 | I8: =170/D9*27 -> 26.344638
A9: 41 | B9: Traspàs C | C9: 42047 | D9: 174.229 | E9: 39.429 | F9: 6869.7 | G9: 6869.7 | H9: 1 | L9: Biotechnology C USD Acc | N9: Traspàs a Asian
A10: 95 | B10: Traspàs V | C10: 42207 | D10: 150 | E10: 39.578 | F10: 5936.65 | G10: 5936.65 | H10: 1 | M10: Biotechnology C USD Acc
A12: Biotechnology C USD Acc
A13: 7 | B13: Compra | C13: 41492 | D13: 24.092 | E13: 250.441 | F13: 6033.63 | G13: 6033.63 | H13: 1 | I13: =D13 -> 24.092 | N13: Compra inicial. | P13: =I13*E13 -> 6033.6246
A14: 39 | B14: Traspàs C | C14: 41673 | D14: 3.144 | E14: 304.866 | F14: 958.5 | G14: 958.5 | H14: 1 | I14: =+I8-I13 -> 2.2526384 | L14: European Growth N Acc ? | N14: Traspàs a Dexia
A15: 40 | B15: Traspàs V | C15: 42047 | D15: 15 | E15: 457.98 | F15: 6869.7 | G15: 6869.7 | H15: 1 | I15: =+I14/D14*D21 -> 53.736603 | M15: Asian Smaller Companies Fund | N15: Traspàs a Asian
A16: 96 | B16: Traspàs C | C16: 42208 | D16: 10.043 | E16: 591.123 | F16: 5936.65 | G16: 5936.65 | H16: 1 | L16: Asian Smaller Companies Fund
A17: 104 | B17: Traspàs C | C17: 42311 | D17: 0.047 | E17: 507.021 | F17: 23.83 | G17: 23.83 | H17: 1 | L17: European Growth N Acc ?
A19: European
A20: 37 | B20: Compra | C20: 41534 | D20: 76.746 | E20: 13.03 | F20: 1000 | G20: 1000 | H20: 1 | I20: 53.7366 | M20: Compra Inicial. | P20: =I20*D20 -> 4124.0691
A21: 38 | B21: Traspàs V | C21: 41673 | D21: 75 | E21: 12.78 | F21: 958.5 | G21: 958.5 | H21: 1 | L21: Biotechnology C USD Acc | M21: Traspàs a Dexia | P21: =SUM(P13:P20) -> 10157.694
A22: 103 | B22: Traspàs V | C22: 42310 | D22: 1.746 | E22: 13.648 | F22: 23.83 | G22: 23.83 | H22: 1 | L22: Biotechnology C USD Acc | P22: =P21/170 -> 59.751139
A26: Deutch
A27: 26 | B27: Traspàs C | C27: 41439 | D27: 249.3471 | E27: 139.71 | F27: 34836.28 | G27: 34836.28 | H27: 25 | L27: Total Return N Acc €-H1
A28: 28 | B28: Traspàs V | C28: 41794 | D28: 249 | E28: 172.04 | F28: 42837.96 | G28: 42837.96 | M28: Optimal Income A-H Grs Acc Hdg EUR
A30: 31 | B30: Traspàs C | C30: 41976 | D30: 264.1805 | E30: 168.57 | F30: 44532.91 | G30: 44532.91 | H30: 30 | L30: Optimal Income A-H Grs Acc Hdg EUR
A31: 91 | B31: Traspàs V | C31: 42201 | D31: 259.53 | E31: 207.11 | F31: 53751.26 | G31: 53751.26 | M31: Optimal Income A-H Grs Acc Hdg EUR
A33: Optimal Income
A34: 27 | B34: Compra | C34: 41521 | D34: 58.502 | E34: 17.093 | F34: 999.99 | G34: 999.99 | I34: 58.502 | K34: =I34*E34 -> 999.97469
A35: 29 | B35: Traspàs C | C35: 41794 | D35: 2347.326 | E35: 18.25 | F35: 42837.96 | G35: 42837.96 | H35: 28 | L35: Deutschland
A36: 30 | B36: Traspàs V | C36: 41971 | D36: 2404 | E36: 18.525 | F36: 44532.91 | G36: 44532.91 | M36: Deutschland
A38: Total Return
A39: 16 | B39: Compra | C39: 41166 | D39: 547.6451 | E39: 18.26 | F39: 10000 | G39: 10000 | I39: 2.5590151 | J39: 547.64513
A40: 17 | B40: Compra | C40: 41377 | D40: 1010.611 | E40: 19.79 | F40: 19999.99 | G40: 19999.99 | I40: 1010.611
A41: 24 | B41: Traspàs C | C41: 41383 | D41: 280.07 | E41: 19.68 | F41: 5511.77 | G41: 5511.77 | H41: 23 | L41: Bolsa Tecnología y Telecomunicaciones FI
A42: 25 | B42: Traspàs V | C42: 41439 | D42: 1838.3261 | E42: 18.95 | F42: 34836.28 | G42: 34836.28 | M42: Deutschland
A44: Bolsa Tecnología y Telecomunicaciones FI
A45: 15 | B45: Compra | C45: 36841 | D45: 679.64 | E45: 22.992 | F45: 15626.31 | G45: 15626.31 | I45: 583.65273
A46: 23 | B46: Traspàs V | C46: 41383 | D46: 679.64 | E46: 8.11 | F46: 5511.77 | G46: 5511.77 | L46: Total Return N Acc €-H1 | M46: Traspàs a Templeton Total return
